Workbook

Sheet Read Me
A1: American Built Cabinets - Cleaned Keyword Map
A2: Source: Semrush Keyword Strategy Builder export (767 keywords), audited 23 July 2026.
A4: What was done
A5: The original export mapped 767 keywords across 32 URLs. 313 were removed and 71 flagged for review.
A6: Removals fall into eight buckets, each named in the 'Cut List' tab so you can overrule any of them.
A7: The largest single problem was audience drift: keywords about kitchen remodeling, DIY cabinet
A8: building, cabinet painting, furniture retail and San Jose community events. None of these
A9: describe someone commissioning custom cabinetry from a manufacturer.
A11: Tabs
A12: Priority Map - the 383 keywords worth keeping, grouped into 15 clusters with a target page.
A13: Cluster Summary - volume and difficulty per cluster, with build order. Start here.
A14: Gaps to Add - keywords the strategy file missed entirely, pulled from your Positions export
... A32: see the Gaps to Add tab.

Sheet Cluster Summary
A1: Cluster Summary - build order
A2: Keywords and Volume are live SUMIFS/COUNTIFS against the Priority Map tab.
A4: Cluster | B4: Target page | C4: Keywords | D4: Total Vol | E4: Med KD | F4: Priority | G4: Page status | H4: Action
A5: Door styles & cabinet types | B5: /colors-finishes | C5: =COUNTIF('Priority Map'!$A:$A,$A5) -> 65 | D5: =SUMIF('Priority Map'!$A:$A,$A5,'Priority Map'!$D:$D) -> 27820 | E5: 23 | G5: Exists | H5: Split into 3 pages - it is carrying 65 keywords alone
A6: Two-tone & cabinet colors | B6: /blog/two-tone-kitchen-cabinets... | C6: =COUNTIF('Priority Map'!$A:$A,$A6) -> 54 | D6: =SUMIF('Priority Map'!$A:$A,$A6,'Priority Map'!$D:$D) -> 22850 | E6: 24 | G6: Exists | H6: Expand; strongest colour cluster
A7: Materials: MDF/plywood/wood | B7: /blog/mdf-vs-plywood-vs-solid-wood... | C7: =COUNTIF('Priority Map'!$A:$A,$A7) -> 44 | D7: =SUMIF('Priority Map'!$A:$A,$A7,'Priority Map'!$D:$D) -> 18770 | E7: 19.5 | G7: Exists | H7: Expand; low KD across the board
A8: Shaker style | B8: /blog/modern-shaker-cabinets... | C8: =COUNTIF('Priority Map'!$A:$A,$A8) -> 52 | D8: =SUMIF('Priority Map'!$A:$A,$A8,'Priority Map'!$D:$D) -> 17390 | E8: 17 | G8: Exists | H8: Make this a pillar page - median KD 17
A9: Dining room cabinets | B9: /blog/modern-dining-room-cabinet-solutions... | C9: =COUNTIF('Priority Map'!$A:$A,$A9) -> 25 | D9: =SUMIF('Priority Map'!$A:$A,$A9,'Priority Map'!$D:$D) -> 11180 | E9: 20 | G9: Exists | H9: Check intent - much of this is furniture shopping
A10: Finishes: paint vs stain | B10: /blog/cabinet-finishes-explained... | C10: =COUNTIF('Priority Map'!$A:$A,$A10) -> 51 | D10: =SUMIF('Priority Map'!$A:$A,$A10,'Priority Map'!$D:$D) -> 8210 | E10: 15 | G10: Exists | H10: Expand; median KD 15, lowest on the site
A11: Installation service | B11: /service/installation | C11: =COUNTIF('Priority Map'!$A:$A,$A11) -> 11 | D11: =SUMIF('Priority Map'!$A:$A,$A11,'Priority Map'!$D:$D) -> 5690 | E11: 28 | G11: Exists | H11: Add local modifiers
A12: Design consultation | B12: /service/design-consultation | C12: =COUNTIF('Priority Map'!$A:$A,$A12) -> 14 | D12: =SUMIF('Priority Map'!$A:$A,$A12,'Priority Map'!$D:$D) -> 5290 | E12: 32.5 | G12: Exists | H12: Thin - needs real content
A13: Custom cabinetry - general | B13: /service | C13: =COUNTIF('Priority Map'!$A:$A,$A13) -> 15 | D13: =SUMIF('Priority Map'!$A:$A,$A13,'Priority Map'!$D:$D) -> 3390 | E13: 36 | G13: Exists | H13: Split trade vs residential
A14: Local: Bay Area & SF | B14: /service | C14: =COUNTIF('Priority Map'!$A:$A,$A14) -> 14 | D14: =SUMIF('Priority Map'!$A:$A,$A14,'Priority Map'!$D:$D) -> 2550 | E14: 18 | G14: Exists | H14: Split trade vs residential
A15: Quality & brand comparison | B15: /about | C15: =COUNTIF('Priority Map'!$A:$A,$A15) -> 11 | D15: =SUMIF('Priority Map'!$A:$A,$A15,'Priority Map'!$D:$D) -> 2210 | E15: 13 | G15: Exists | H15: Stop competing with homepage on brand terms
A16: Commercial cabinetry | B16: /commercial (NEW PAGE) | C16: =COUNTIF('Priority Map'!$A:$A,$A16) -> 5 | D16: =SUMIF('Priority Map'!$A:$A,$A16,'Priority Map'!$D:$D) -> 1510 | E16: 8 | G16: MISSING | H16: Build it - median KD 8, currently on a portfolio page
... A19: Local: San Jose | B19: / (homepage) | C19: =COUNTIF('Priority Map'!$A:$A,$A19) -> 11 | D19: =SUMIF('Priority Map'!$A:$A,$A19,'Priority Map'!$D:$D) -> 560 | E19: 23 | G19: Exists | H19: See Gaps tab - the real San Jose terms are missing here
B21: TOTAL | C21: =SUM(C5:C19) -> 383 | D21: =SUM(D5:D19) -> 129360
A23: Priority column left blank deliberately - fill it in yourself. Ranking these is a business decision about which customer you want more of (homeowner, builder, or commercial), not an SEO one.

Sheet Priority Map
A1: Cluster | B1: Target page | C1: Keyword | D1: Vol | E1: KD | F1: Score | G1: Intent | H1: Note
A2: Commercial cabinetry | B2: /commercial (NEW PAGE) | C2: commercial cabinets | D2: 1000 | E2: 19 | F2: =IF(E2<=1,"",ROUND(D2/POWER(E2,0.9),1)) -> 70.7 | G2: commercial
A3: Commercial cabinetry | B3: /commercial (NEW PAGE) | C3: commercial cabinetry | D3: 320 | E3: 8 | F3: =IF(E3<=1,"",ROUND(D3/POWER(E3,0.9),1)) -> 49.2 | G3: commercial
A4: Commercial cabinetry | B4: /commercial (NEW PAGE) | C4: commercial grade cabinets | D4: 110 | E4: 3 | F4: =IF(E4<=1,"",ROUND(D4/POWER(E4,0.9),1)) -> 40.9 | G4: commercial
A5: Commercial cabinetry | B5: /commercial (NEW PAGE) | C5: commercial building cabinet | D5: 40 | E5: 11 | F5: =IF(E5<=1,"",ROUND(D5/POWER(E5,0.9),1)) -> 4.6 | G5: informational, transactional
A6: Commercial cabinetry | B6: /commercial (NEW PAGE) | C6: custom commercial cabinetry | D6: 40 | E6: 0 | F6: =IF(E6<=1,"",ROUND(D6/POWER(E6,0.9),1)) | G6: commercial | H6: KD unavailable
A7: Cost & pricing | B7: /pricing (NEW PAGE) | C7: custom cabinet cost | D7: 260 | E7: 8 | F7: =IF(E7<=1,"",ROUND(D7/POWER(E7,0.9),1)) -> 40 | G7: informational, commercial
A8: Cost & pricing | B8: /pricing (NEW PAGE) | C8: custom cabinets prices | D8: 390 | E8: 30 | F8: =IF(E8<=1,"",ROUND(D8/POWER(E8,0.9),1)) -> 18.3 | G8: commercial
A9: Cost & pricing | B9: /pricing (NEW PAGE) | C9: kitchen cabinets pricing | D9: 260 | E9: 24 | F9: =IF(E9<=1,"",ROUND(D9/POWER(E9,0.9),1)) -> 14.9 | G9: transactional
A10: Cost & pricing | B10: /pricing (NEW PAGE) | C10: cabinet pricing | D10: 210 | E10: 27 | F10: =IF(E10<=1,"",ROUND(D10/POWER(E10,0.9),1)) -> 10.8 | G10: transactional
A11: Custom cabinetry - general | B11: /service | C11: custom made cabinets | D11: 1000 | E11: 44 | F11: =IF(E11<=1,"",ROUND(D11/POWER(E11,0.9),1)) -> 33.2 | G11: commercial
A12: Custom cabinetry - general | B12: /service | C12: custom cabinets for bedroom | D12: 30 | E12: 2 | F12: =IF(E12<=1,"",ROUND(D12/POWER(E12,0.9),1)) -> 16.1 | G12: informational
A13: Custom cabinetry - general | B13: /service | C13: custom cabinets for bathroom | D13: 320 | E13: 29 | F13: =IF(E13<=1,"",ROUND(D13/POWER(E13,0.9),1)) -> 15.5 | G13: commercial
A14: Custom cabinetry - general | B14: /service | C14: customizable cabinets | D14: 390 | E14: 39 | F14: =IF(E14<=1,"",ROUND(D14/POWER(E14,0.9),1)) -> 14.4 | G14: commercial
A15: Custom cabinetry - general | B15: /service | C15: building custom cabinets | D15: 260 | E15: 29 | F15: =IF(E15<=1,"",ROUND(D15/POWER(E15,0.9),1)) -> 12.6 | G15: informational
A16: Custom cabinetry - general | B16: /service | C16: custom oak cabinets | D16: 90 | E16: 10 | F16: =IF(E16<=1,"",ROUND(D16/POWER(E16,0.9),1)) -> 11.3 | G16: commercial
A17: Custom cabinetry - general | B17: /service | C17: custom cabinets for kitchen | D17: 260 | E17: 36 | F17: =IF(E17<=1,"",ROUND(D17/POWER(E17,0.9),1)) -> 10.3 | G17: commercial
A18: Custom cabinetry - general | B18: /service | C18: custom base cabinets | D18: 170 | E18: 31 | F18: =IF(E18<=1,"",ROUND(D18/POWER(E18,0.9),1)) -> 7.7 | G18: commercial
... A63: Dining room cabinets | B63: /blog/modern-dining-room-cabinet-solutions... | C63: tall cabinets for dining room | D63: 30 | E63: 16 | F63: =IF(E63<=1,"",ROUND(D63/POWER(E63,0.9),1)) -> 2.5 | G63: transactional
A64: Dining room cabinets | B64: /blog/modern-dining-room-cabinet-solutions... | C64: custom dining room cabinets | D64: 70 | E64: 0 | F64: =IF(E64<=1,"",ROUND(D64/POWER(E64,0.9),1)) | G64: commercial | H64: KD unavailable
A65: Door styles & cabinet types | B65: /colors-finishes | C65: cabinet door styles | D65: 3600 | E65: 26 | F65: =IF(E65<=1,"",ROUND(D65/POWER(E65,0.9),1)) -> 191.8 | G65: informational, commercial
A66: Door styles & cabinet types | B66: /colors-finishes | C66: cabinet design | D66: 3600 | E66: 34 | F66: =IF(E66<=1,"",ROUND(D66/POWER(E66,0.9),1)) -> 150.7 | G66: commercial
A67: Door styles & cabinet types | B67: /colors-finishes | C67: types of cabinet doors | D67: 1300 | E67: 11 | F67: =IF(E67<=1,"",ROUND(D67/POWER(E67,0.9),1)) -> 150.2 | G67: informational
A68: Door styles & cabinet types | B68: /colors-finishes | C68: cabinet styles | D68: 2400 | E68: 25 | F68: =IF(E68<=1,"",ROUND(D68/POWER(E68,0.9),1)) -> 132.5 | G68: informational
A69: Door styles & cabinet types | B69: /colors-finishes | C69: types of cabinets | D69: 1600 | E69: 26 | F69: =IF(E69<=1,"",ROUND(D69/POWER(E69,0.9),1)) -> 85.2 | G69: informational
A70: Door styles & cabinet types | B70: /colors-finishes | C70: type of cabinet | D70: 590 | E70: 12 | F70: =IF(E70<=1,"",ROUND(D70/POWER(E70,0.9),1)) -> 63 | G70: informational
A71: Door styles & cabinet types | B71: /colors-finishes | C71: cabinet designs | D71: 1000 | E71: 23 | F71: =IF(E71<=1,"",ROUND(D71/POWER(E71,0.9),1)) -> 59.5 | G71: informational, commercial
A72: Door styles & cabinet types | B72: /colors-finishes | C72: kitchen cabinet designer | D72: 1000 | E72: 36 | F72: =IF(E72<=1,"",ROUND(D72/POWER(E72,0.9),1)) -> 39.7 | G72: commercial
A73: Door styles & cabinet types | B73: /colors-finishes | C73: style of cabinet doors | D73: 480 | E73: 17 | F73: =IF(E73<=1,"",ROUND(D73/POWER(E73,0.9),1)) -> 37.5 | G73: informational
A74: Door styles & cabinet types | B74: /colors-finishes | C74: modern cabinet door styles | D74: 720 | E74: 27 | F74: =IF(E74<=1,"",ROUND(D74/POWER(E74,0.9),1)) -> 37.1 | G74: informational
A75: Door styles & cabinet types | B75: /colors-finishes | C75: pictures of kitchen cabinet styles | D75: 720 | E75: 27 | F75: =IF(E75<=1,"",ROUND(D75/POWER(E75,0.9),1)) -> 37.1 | G75: informational
A76: Door styles & cabinet types | B76: /colors-finishes | C76: modern kitchen cabinet design | D76: 880 | E76: 34 | F76: =IF(E76<=1,"",ROUND(D76/POWER(E76,0.9),1)) -> 36.8 | G76: informational
... A179: Finishes: paint vs stain | B179: /blog/cabinet-finishes-explained... | C179: cabinet finishes paint | D179: 40 | E179: 23 | F179: =IF(E179<=1,"",ROUND(D179/POWER(E179,0.9),1)) -> 2.4 | G179: informational
A180: Finishes: paint vs stain | B180: /blog/cabinet-finishes-explained... | C180: painted cabinets vs stained | D180: 30 | E180: 1 | F180: =IF(E180<=1,"",ROUND(D180/POWER(E180,0.9),1)) | G180: commercial | H180: KD unavailable
A181: Installation service | B181: /service/installation | C181: kitchen cabinet installation | D181: 2400 | E181: 28 | F181: =IF(E181<=1,"",ROUND(D181/POWER(E181,0.9),1)) -> 119.6 | G181: commercial
A182: Installation service | B182: /service/installation | C182: cabinet installer | D182: 1300 | E182: 43 | F182: =IF(E182<=1,"",ROUND(D182/POWER(E182,0.9),1)) -> 44 | G182: commercial
A183: Installation service | B183: /service/installation | C183: cabinet installers | D183: 720 | E183: 37 | F183: =IF(E183<=1,"",ROUND(D183/POWER(E183,0.9),1)) -> 27.9 | G183: commercial
A184: Installation service | B184: /service/installation | C184: installation of cabinets | D184: 390 | E184: 28 | F184: =IF(E184<=1,"",ROUND(D184/POWER(E184,0.9),1)) -> 19.4 | G184: informational
A185: Installation service | B185: /service/installation | C185: installation cabinets | D185: 390 | E185: 31 | F185: =IF(E185<=1,"",ROUND(D185/POWER(E185,0.9),1)) -> 17.7 | G185: commercial
A186: Installation service | B186: /service/installation | C186: custom cabinet installation | D186: 210 | E186: 41 | F186: =IF(E186<=1,"",ROUND(D186/POWER(E186,0.9),1)) -> 7.4 | G186: commercial
...

Sheet Gaps to Add
A1: Keywords the strategy file missed
A2: Sourced from your Organic Positions export and the Otterly AI brand report. The first three are the single biggest omission: a cluster you already rank #13 for.
A4: Keyword | B4: Vol | C4: KD | D4: Intent | E4: Target page | F4: Why it matters
A5: inset vs overlay cabinets | B5: 1900 | C5: 10 | D5: commercial | E5: /blog/inset-vs-overlay-cabinets... | F5: Ranks #13 already. Whole cluster absent from strategy file.
A6: inset cabinets vs overlay cabinets | B6: 720 | C6: 9 | D6: commercial | E6: /blog/inset-vs-overlay-cabinets... | F6: Ranks #30. Same page.
A7: inset cabinets vs overlay | B7: 590 | C7: 8 | D7: commercial | E7: /blog/inset-vs-overlay-cabinets... | F7: Ranks #37. Same page.
A8: kitchen cabinets san jose ca | B8: 170 | C8: 16 | D8: commercial | E8: / (homepage) | F8: Ranks #31. Highest-volume San Jose term; missing from strategy.
A9: san jose ca cabinets | B9: 70 | C9: 28 | D9: commercial | E9: / (homepage) | F9: Ranks #24. Missing from strategy.
A10: cabinet makers in san jose ca | B10: 40 | C10: 20 | D10: commercial | E10: / (homepage) | F10: Ranks #68. CPC $6.09.
A11: cabinet maker san jose ca | B11: 30 | C11: 21 | D11: commercial | E11: / (homepage) | F11: Ranks #15. CPC $7.10 - highest-value term on the site.
A12: cabinet store san jose | B12: 30 | C12: 8 | D12: commercial | E12: / (homepage) | F12: Ranks #26, new entry. KD 8.
A13: ikea cabinets installation service | B13: 50 | C13: 28 | D13: informational | E13: /service/installation | F13: Ranks #69. CPC $5.47.
A14: custom cabinet lead time | B14: n/a | C14: n/a | D14: commercial | E14: /blog/how-long-do-custom-kitchen-cabinets-take... | F14: No Semrush volume, but drove 20 AI citations (Otterly prompt #1). Build for AI search, not Google.
A15: cabinet lead times bay area | B15: n/a | C15: n/a | D15: commercial | E15: /blog/how-long-do-custom-kitchen-cabinets-take... | F15: Same - AI-search demand that Semrush cannot see.
A16: cabinet supplier for home builders | B16: n/a | C16: n/a | D16: commercial | E16: /trade-program | F16: Otterly prompt #3. Zero Semrush volume, real buyer question.
A17: integrated material solutions cabinetry | B17: n/a | C17: n/a | D17: commercial | E17: /trade-program | F17: Otterly prompt #1 by mention count.

Sheet Cut List
A1: Removed keywords
A2: Overrule anything here that you disagree with - these are rules, not judgements about your business.
A4: Keyword | B4: Vol | C4: KD | D4: Intent | E4: Reason cut
A5: diy kitchen cabinets | B5: 3600 | C5: 40 | D5: informational | E5: DIY / woodworking hobbyist
A6: how to make kitchen cabinets | B6: 1600 | C6: 20 | D6: informational | E6: DIY / woodworking hobbyist
A7: how to build kitchen cabinets | B7: 1600 | C7: 29 | D7: informational | E7: DIY / woodworking hobbyist
A8: kitchen cabinet plans | B8: 720 | C8: 9 | D8: commercial | E8: DIY / woodworking hobbyist
A9: build cabinets | B9: 480 | C9: 18 | D9: informational | E9: DIY / woodworking hobbyist
A10: building a cabinet | B10: 480 | C10: 22 | D10: informational | E10: DIY / woodworking hobbyist
A11: kitchen cabinet blueprints | B11: 390 | C11: 14 | D11: informational, commercial | E11: DIY / woodworking hobbyist
A12: good wood for cabinet making | B12: 320 | C12: 13 | D12: informational, commercial | E12: DIY / woodworking hobbyist
A13: woodworking cabinets | B13: 320 | C13: 45 | D13: commercial | E13: DIY / woodworking hobbyist
A14: how do you build kitchen cabinets | B14: 320 | C14: 28 | D14: informational | E14: DIY / woodworking hobbyist
A15: how to make custom cabinets | B15: 260 | C15: 21 | D15: informational | E15: DIY / woodworking hobbyist
A16: build your own custom cabinets | B16: 260 | C16: 38 | D16: informational, transactional | E16: DIY / woodworking hobbyist
... A317: cabinet makers and installers near me | B317: 30 | C317: 38 | D317: transactional | E317: Retail / e-commerce intent

Sheet Review
A1: Unclustered - needs a human decision
A2: These passed the cut rules but matched no cluster pattern. Assign or discard.
A4: Keyword | B4: Vol | C4: KD | D4: Intent | E4: Originally assigned to
A5: coffee bar cabinet | B5: 22200 | C5: 30 | D5: informational, commercial | E5: (unassigned)
A6: white kitchen cabinets | B6: 18100 | C6: 37 | D6: informational | E6: (unassigned)
A7: kitchen storage cabinets | B7: 8100 | C7: 39 | D7: transactional | E7: (unassigned)
A8: kitchen cabinets paint | B8: 3600 | C8: 36 | D8: informational, commercial | E8: (unassigned)
A9: base kitchen cabinets | B9: 2400 | C9: 36 | D9: transactional | E9: (unassigned)
A10: cabinet building | B10: 880 | C10: 24 | D10: informational | E10: (unassigned)
A11: kitchen cabinets wooden | B11: 720 | C11: 28 | D11: transactional | E11: (unassigned)
A12: kitchen cabinets pictures gallery | B12: 590 | C12: 25 | D12: informational | E12: (unassigned)
A13: kitchen trends 2026 | B13: 590 | C13: 20 | D13: informational | E13: (unassigned)
A14: type of kitchen cabinets | B14: 480 | C14: 22 | D14: informational | E14: (unassigned)
A15: cabinet solutions | B15: 480 | C15: 28 | D15: commercial | E15: (unassigned)
A16: types of kitchen cabinet | B16: 480 | C16: 23 | D16: informational | E16: /blog
... A75: kitchen cabinet type | B75: 30 | C75: 21 | D75: informational, commercial | E75: (unassigned)
